I'm sorry, but an uncaught exception occurred.

While running game code:
  File "game/script.rpy", line 260, in script
    if CarryBox and TechSkill == 0:
  File "game/script.rpy", line 260, in <module>
    if CarryBox and TechSkill == 0:
NameError: name 'CarryBox' is not defined

-- Full Traceback ------------------------------------------------------------

Full traceback:
  File "game/script.rpy", line 260, in script
    if CarryBox and TechSkill == 0:
  File "C:\Users\court\Documents\PS GitHub\projectself\PS PC Build 12_12_24\renpy\ast.py", line 1843, in execute
    if renpy.python.py_eval(condition):
  File "C:\Users\court\Documents\PS GitHub\projectself\PS PC Build 12_12_24\renpy\python.py", line 1209, in py_eval
    return py_eval_bytecode(code, globals, locals)
  File "C:\Users\court\Documents\PS GitHub\projectself\PS PC Build 12_12_24\renpy\python.py", line 1202, in py_eval_bytecode
    return eval(bytecode, globals, locals)
  File "game/script.rpy", line 260, in <module>
    if CarryBox and TechSkill == 0:
NameError: name 'CarryBox' is not defined

Windows-10-10.0.19045 AMD64
Ren'Py 8.3.3.24111502
Project Self 1.0
Thu Dec 12 10:17:09 2024
